Workbook

Sheet RelayData
A1: Gender | B1: Event | C1: Age Group | D1: IDR | E1: Mark | F1: Team Name | G1: Athlete01 | H1: DOB1 | I1: Athlete02 | J1: DOB2 | K1: Athlete03 | L1: DOB3 | M1: Athlete04 | N1: DOB4 | O1: Date | P1: Town | Q1: Race Name
A2: Male | B2: 4x100 | C2: 35 | D2: Α | E2: 44.86 | F2: Μικτή Ομάδα | G2: Αφρουδάκης, Παναγιώτης | H2: 21.1.1977 | I2: Λεπίδας, Γεώργιος | J2: 25.7.1975 | K2: Καπασούζ, Ιορδάνης | L2: 29.8.1980 | M2: Φιωτάκης, Χρήστος | N2: 8.6.1980 | O2: 42265 | P2: Θεσσαλονίκη | Q2: Βαλκανικό Πρωτάθλημα
A3: Male | B3: 4x100 | C3: 40 | D3: Α | E3: 47.18 | F3: Μικτή Ομάδα | G3: Χατζηνικολάου, Νικόλαος | H3: 27.12.1966) | I3: Κοντονής, Διονύσιος | J3: 6.2.1969 | K3: Σιάμος, Περικλής | L3: 9.1.1964 | M3: Ζογλοπίτης, Ιωάννης | N3: 2.9.1968 | O3: 40789 | P3: Ντόμζαλε, Σλοβενία | Q3: Βαλκανικό Πρωτάθλημα
A4: Male | B4: 4x100 | C4: 45 | D4: Α | E4: 47.91 | F4: Μικτή Ομάδα | G4: Χατζηστέργος, Στέργιος | H4: 2.11.1968 | I4: Χατζηνικολάου, Νικόλαος | J4: 27.12.1966) | K4: Κοντονής, Διονύσιος | L4: 6.2.1969 | M4: Αργυρόπουλος, Διονύσιος | N4: 4.8.1969 | O4: 41902 | P4: Βουκουρέστι, Ρουμανία | Q4: Βαλκανικό Πρωτάθλημα
A5: Male | B5: 4x100 | C5: 50 | D5: Α | E5: 50.89 | F5: Μικτή Ομάδα | G5: Χατζηιωακειμήδης, Χαράλαμπος | H5: 22.01.1972 | I5: Κοντονής, Διονύσιος | J5: 6.2.1969 | K5: Ανδρομιδάς, Νικόλαος | L5: 15.04.1972) | M5: Παπάζογλου, Αθανάσιος | N5: 21.11.1970) | O5: 44827 | P5: Θεσσαλονίκη | Q5: Βαλκανικό Πρωτάθλημα
A6: Male | B6: 4x100 | C6: 55 | D6: Α | E6: 52.40 | F6: Μικτή Ομάδα | G6: Χουλίδης, Ιωάννης | H6: 25.8.1952 | I6: Σκορδίλης, Σπυρίδων | J6: 10.7.1960 | K6: Μπακάλης, Σπυρίδων | L6: 19.3.1958 | M6: Αλέξης, Γεώργιος | N6: 3.5.1959 | O6: 42265 | P6: Θεσσαλονίκη | Q6: Βαλκανικό Πρωτάθλημα
A7: Male | B7: 4x100 | C7: 60 | D7: Α | E7: 54.91 | F7: Μικτή Ομάδα | G7: Χαϊτίδης, Δημήτριος | H7: 24.03.1958 | I7: Τσιγγιζής, Παντελής | J7: 17.10.1960 | K7: Χατζηαθανασίου, Συμεών | L7: 13.02.1961 | M7: Σκορδίλης, Σπυρίδων | N7: 10.7.1960 | O7: 45170 | P7: Σμύρνη, Τουρκία | Q7: Βαλκανικό Πρωτάθλημα
A8: Male | B8: 4x100 | C8: 65 | D8: Α | E8: 56.31 | F8: Μικτή Ομάδα | G8: Ανδρεάδης, Βασίλειος | H8: 14.2.1954 | I8: Χαραλαμπίδης, Παύλος | J8: 21.8.1948 | K8: Συμεωνίδης, Ευστράτιος | L8: 24.1.1954 | M8: Δρουδάκης, Ιωάννης | N8: 16.8.1953 | O8: 43729 | P8: Βουκουρέστι, Ρουμανία | Q8: Βαλκανικό Πρωτάθλημα
A9: Male | B9: 4x100 | C9: 70 | D9: Α | E9: 1.02.83 | F9: Μικτή Ομάδα | G9: Χαραλαμπίδης, Παύλος | H9: 21.8.1948 | I9: Χρυσοχός, Παντελής | J9: 15.10.1951 | K9: Ομηρίδης, Δημήτριος | L9: 10.01.1945 | M9: Λυρατζάκης, Ιωάννης | N9: 05.05.1949 | O9: 44827 | P9: Θεσσαλονίκη | Q9: Βαλκανικό Πρωτάθλημα
A10: Male | B10: 4x100 | C10: 75 | D10: Α | E10: 1.14.43 | F10: Μικτή Ομάδα | G10: Χατζηεμμανουήλ, Κωνσταντίνος | H10: 25.1.1929 | I10: Μπέκος, Αναστάσιος | J10: 8.2.1935 | K10: Συμεωνίδης, Συμεών | L10: 23.12.1933 | M10: Καπασακάλης, Κοσμάς | N10: 9.6.1934 | O10: 42265 | P10: Θεσσαλονίκη | Q10: Βαλκανικό Πρωτάθλημα
A11: Male | B11: 4x100 | C11: 80 | D11: Α | E11: 1.33.98 | F11: Μικτή Ομάδα | G11: Χατζηεμμανουήλ, Κωνσταντίνος | H11: 25.1.1929 | I11: Δούσης, Παναγιώτης | J11: 23.09.1933 | K11: Δημητρόπουλος, Κωνσταντίνος | L11: 13.10.1937 | M11: Αλλίμονος, Γεώργιος | N11: 20.02.1942 | O11: 44827 | P11: Θεσσαλονίκη | Q11: Βαλκανικό Πρωτάθλημα
A12: Male | B12: 4x400 | C12: 35 | D12: Α | E12: 3.45.11 | F12: ΣΥΒΑΣ Λάρισας | G12: Γκουζώνης, Γεώργιος | H12: 17.4.1980 | I12: Κυριάκος, Ιωάννης | J12: 9.2.1979 | K12: Ψαρογιώργος, Χρήστος | L12: 24.11.1974 | M12: Δημότσιος, Στυλιανός | N12: 13.11.1974 | O12: 42917 | P12: Λάρισα | Q12: Πανελλήνιο Πρωτάθλημα
A13: Male | B13: 4x400 | C13: 40 | D13: Α | E13: 3.54.30 | F13: Μικτή Ομάδα | G13: Αρμάος, Ιούλιος | H13: 4.4.1977 | I13: Κωνσταντινίδης, Χαράλαμπος | J13: 1.6.1974 | K13: Κουτσώνας, Αλέξανδρος | M13: Κουρής, Νικόλαος | O13: 43121 | P13: Αθήνα, Αγ. Κοσμάς | Q13: Ημερίδα
A14: Male | B14: 4x400 | C14: 45 | D14: Α | E14: 4.01.45 | F14: Μικτή Ομάδα | G14: Κόκκος, Νικόλαος | H14: 2.10.1969 | I14: Μπέσσας, Ανδρέας | J14: 26.6.1969 | K14: Σιάμος, Περικλής | L14: 9.1.1964 | M14: Σκορδίλης, Σπυρίδων | N14: 10.7.1960 | O14: 43121 | P14: Αθήνα, Αγ. Κοσμάς | Q14: Ημερίδα
A15: Male | B15: 4x400 | C15: 50 | D15: Α | E15: 4.03.90 | F15: Μικτή Ομάδα | G15: Παπάζογλου, Αθανάσιος | H15: 21.11.1970) | I15: Κοντονής, Διονύσιος | J15: 6.2.1969 | K15: Τσιώλης, Κωνσταντίνος | L15: 17.5.1972 | M15: Κόκκος, Νικόλαος | N15: 2.10.1969 | O15: 44829 | P15: Θεσσαλονίκη | Q15: Βαλκανικό Πρωτάθλημα
A16: Male | B16: 4x400 | C16: 55 | D16: Α | E16: 4.17.6 | F16: Μικτή Ομάδα | G16: Σκορδίλης, Σπυρίδων | H16: 10.7.1960 | I16: Κομματάς, Κωνσταντίνος | J16: 28.10.1957 | K16: Μακαντάνης, Βασίλειος | L16: 1.3.1961 | M16: Άγρος, Οδυσσέας | N16: 30.10.1957 | O16: 42910 | P16: Αθήνα | Q16: Ημερίδα
A17: Male | B17: 4x400 | C17: 60 | D17: Α | E17: 4.42.08 | F17: Μικτή Ομάδα | G17: Κουνούπης, Γ. | H17: 20.6.1957 | I17: Κομματάς, Κωνσταντίνος | J17: 28.10.1957 | K17: Κυρίμης, Δημήτριος | L17: 24.2.1956 | M17: Άγρος, Οδυσσέας | N17: 30.10.1957 | O17: 43121 | P17: Αθήνα | Q17: Ημερίδα
A18: Male | B18: 4x400 | C18: 65 | D18: Α | E18: 5.08.73 | F18: Μικτή Ομάδα | G18: Συμεωνίδης, Ευστράτιος | H18: 24.1.1954 | I18: Δρουδάκης, Ιωάννης | J18: 16.8.1953 | K18: Χαϊτίδης, Δημήτριος | L18: 24.03.1958 | M18: Βλάχος, Ιωάννης | N18: 26.01.1953 | O18: 45171 | P18: Σμύρνη, Τουρκία | Q18: Βαλκανικό Πρωτάθλημα
A19: Male | B19: 4x400 | C19: 70 | D19: Α | E19: 5.56.52 | F19: Μικτή Ομάδα | G19: Μπασδέκης, Παύλος | H19: 20.5.1946 | I19: Παπαδάτος, Κωνσταντίνος | J19: 1.11.1945 | K19: Μάρας, Αριστείδης | L19: 27.2.1946 | M19: Διακάτος, Λ. | N19: 21.10.1943 | O19: 43121 | P19: Αθήνα | Q19: Ημερίδα
A20: Male | B20: Βαλκανική Σκυτάλη | C20: 35 | D20: Α | E20: 3.44.40 | F20: Εθνική Ομάδα | G20: Λεπίδας, Γεώργιος | H20: 25.7.1975 | I20: Κυριάκος, Ιωάννης | J20: 9.2.1979 | K20: Ψαρογιώργος, Χρήστος | L20: 24.11.1974 | M20: Κόκκος, Νικόλαος | N20: 2.10.1969 | O20: 43002 | P20: Στάρα Ζαγόρα, Βουλγαρία | Q20: Βαλκανικό Πρωτάθλημα
A21: Male | B21: Βαλκανική Σκυτάλη | C21: 40 | D21: Α | E21: 3.44.63 | F21: Εθνική Ομάδα | G21: Χατζηνικολάου, Νικόλαος | H21: 27.12.1966) | I21: Κοντονής, Διονύσιος | J21: 6.2.1969 | K21: Σιάμος, Περικλής | L21: 9.1.1964 | M21: Ζογλοπίτης, Ιωάννης | N21: 2.9.1968 | O21: 40790 | P21: Ντόμζαλε, Σλοβενία | Q21: Βαλκανικό Πρωτάθλημα
A22: Male | B22: Βαλκανική Σκυτάλη | C22: 45 | D22: Α | E22: 3.45.31 | F22: Εθνική Ομάδα | G22: Αρμάος, Ιούλιος | H22: 4.4.1977 | I22: Καταντωνάκης, Αντώνιος | J22: 21.09.1977) | K22: Γιανναδάκης, Νικόλαος | L22: 25.01.1977) | M22: Τσιώλης, Κωνσταντίνος | N22: 17.5.1972 | O22: 44827 | P22: Θεσσαλονίκη | Q22: Βαλκανικό Πρωτάθλημα
A23: Male | B23: Βαλκανική Σκυτάλη | C23: 50 | D23: Α | E23: 4.03.44 | F23: Εθνική Ομάδα | G23: Αρβανίτης, Νικόλαος | H23: 21.8.1967) | I23: ΜακΓκάουαν, Λώρενς | J23: 09.02.1968 | K23: Μπέσσας, Ανδρέας | L23: 26.6.1969 | M23: Ζογλοπίτης, Ιωάννης | N23: 2.9.1968 | O23: 43730 | P23: Βουκουρέστι, Ρουμανία | Q23: Βαλκανικό Πρωτάθλημα
A24: Male | B24: Βαλκανική Σκυτάλη | C24: 55 | D24: Α | E24: 4.07.50 | F24: Εθνική Ομάδα | G24: Σκορδίλης, Σπυρίδων | H24: 10.7.1960 | I24: Κομματάς, Κωνσταντίνος | J24: 28.10.1957 | K24: Χαϊτίδης, Δημήτριος | L24: 24.03.1958 | M24: Χατζηαθανασίου, Συμεών | N24: 13.2.1961 | O24: 43002 | P24: Στάρα Ζαγόρα, Βουλγαρία | Q24: Βαλκανικό Πρωτάθλημα
A25: Male | B25: Βαλκανική Σκυτάλη | C25: 60 | D25: Α | E25: 4.31.5 | F25: Εθνική Ομάδα | G25: Καραγιαννόπουλος, Σ. | H25: 10.7.1960 | I25: Κομματάς, Κωνσταντίνος | J25: 28.10.1957 | K25: Κυρίμης, Δημήτριος | L25: 24.2.1956 | M25: Άγρος, Οδυσσέας | N25: 30.10.1957 | O25: 43240 | P25: Αθήνα | Q25: Ημερίδα
... A29: Female | B29: 4x100 | C29: 35 | D29: Α | E29: 54.40 | F29: Μικτή Ομάδα | G29: Ροκάκη, Αικατερίνη | H29: 18.07.1984 | I29: Λύκου, Φανή | J29: 13.02.1976 | K29: Παναγιωτίδου, Μαρία | L29: 18.11.1979 | M29: Ριζοπούλου, Χρυσάνθη | N29: 18.05.1982 | O29: 44827 | P29: Θεσσαλονίκη | Q29: Βαλκανικό Πρωτάθλημα
A30: Female | B30: 4x100 | C30: 40 | D30: Α | E30: 1.01.23 | F30: Μικτή Ομάδα | G30: Σκονδριάνη, Ελευθερία | H30: 11.10.1976 | I30: Φωτακοπούλου, Ανδριάννα | J30: 21.12.1974 | K30: Σαρρή, Αικατερίνη | L30: 14.10.1976 | M30: Ανυφαντή, Ελένη | O30: 43729 | P30: Βουκουρέστι, Ρουμανία | Q30: Βαλκανικό Πρωτάθλημα
A31: Female | B31: 4x100 | C31: 45 | D31: Α | E31: 57.18 | F31: Μικτή Ομάδα | G31: Μαραγιάννη, Χριστίνα | H31: 25.11.1972 | I31: Δάφτσου, Άννα | J31: 25.09.1970 | K31: Αθανασοπούλου, Κρυσταλλία | L31: 18.05.1970 | M31: Μουρατίδου, Μαρία | N31: 12.3.1967 | O31: 43729 | P31: Βουκουρέστι, Ρουμανία | Q31: Βαλκανικό Πρωτάθλημα
A32: Female | B32: 4x100 | C32: 50 | D32: Α | E32: 1.11.93 | F32: Μικτή Ομάδα | G32: Ευαγγελοπούλου, Καίτη | I32: Σιδερίδου, Παρασκευή | J32: 23.09.1967 | K32: Μπίσκα, Κάτια | M32: Δημητροπούλου, Χρυσούλα | N32: 25.08.1966 | O32: 43729 | P32: Βουκουρέστι, Ρουμανία | Q32: Βαλκανικό Πρωτάθλημα
A33: Female | B33: 4x100 | C33: 55 | D33: Α | E33: 1.17.91 | F33: Μικτή Ομάδα | G33: Βαϊνά, Αθηνά | H33: 8.12.59 | I33: Νάσκου, Θωμαή | J33: 10.09.1967 | K33: Δημητροπούλου, Χρυσούλα | L33: 25.08.1966 | M33: Σιδερίδου, Παρασκευή | N33: 23.09.1967 | O33: 44827 | P33: Θεσσαλονίκη | Q33: Βαλκανικό Πρωτάθλημα
A34: Female | B34: 4x100 | C34: 60 | D34: Α | E34: 1.47.91 | F34: Μικτή Ομάδα | G34: Ιερωνυμάκη, Χ | I34: Αργυρή, Πλούμη | K34: Βαϊνά, Αθηνά | M34: Φιλιππάκη, Αναστασία | N34: 10.04.1971 | O34: 45927 | P34: Ηράκλειο | Q34: Masters Gala
A35: Female | B35: 4x400 | C35: 35 | D35: Α | E35: 6.02.17 | F35: ΣΕΒΑΣ Θεσσαλονίκης | O35: 43632 | P35: Καρδίτσα | Q35: Πανελλήνιο Πρωτάθλημα
A36: Female | B36: 4x400 | C36: 40 | D36: Α | E36: 5.46.06 | F36: Μικτή Ομάδα | G36: Πρασάκη, Ματένια | H36: 04.05.1971 | I36: Βενέτη, Φωτεινή | J36: 22.06.1979 | K36: Αγνωστος | M36: Αγνωστος | O36: 44828 | P36: Θεσσαλονίκη | Q36: Βαλκανικό Πρωτάθλημα
A37: Female | B37: 4x400 | C37: 50 | D37: Α | E37: 7.00.90 | F37: Μικτή Ομάδα | G37: Βαϊνά, Αθηνά | H37: 8.12.59 | I37: Τσαχάκη, Αριάδνη | J37: 02.11.1959 | K37: Νοικοκυράκη, Ελένη | L37: 16.04.1958 | M37: Μπελαδάκη, Αντωνία | N37: 23.05.1969 | O37: 43728 | P37: Βουκουρέστι, Ρουμανία | Q37: Βαλκανικό Πρωτάθλημα
A38: Female | B38: 4x400 | C38: 55 | D38: Α | E38: 6.22.15 | F38: Μικτή Ομάδα | G38: Σουλιώτου, Αλεξάνδρα | H38: 11.04.1965 | I38: Νάσκου, Θωμαή | J38: 10.09.1967 | K38: Νοικοκυράκη, Ελένη | L38: 16.04.1958 | M38: Στεφάνου, Γεωργία | N38: 04.04.1963 | O38: 44828 | P38: Θεσσαλονίκη | Q38: Βαλκανικό Πρωτάθλημα
A39: Female | B39: Βαλκανική Σκυτάλη | C39: 35 | D39: Α | E39: 4.15.03 | F39: Εθνική Ομάδα | G39: Θωμάιδου, Αναστασία | H39: 30.1.1978 | I39: Δάφτσου, Άννα | J39: 25.09.1970 | K39: Λύκου, Φανή | L39: 13.02.1976 | M39: Τραμπίδου, Κυριακή | N39: 1.7.1967 | O39: 42265 | P39: Θεσσαλονίκη | Q39: Βαλκανικό Πρωτάθλημα
A40: Female | B40: Βαλκανική Σκυτάλη | C40: 40 | D40: Α | E40: 4.15.19 | F40: Εθνική Ομάδα | G40: Θωμάιδου, Αναστασία | H40: 30.1.1978 | I40: Γεωργιάδου, Βαρβάρα | J40: 22.01.1980 | K40: Δάφτσου, Άννα | L40: 25.09.1970 | M40: Μουρατίδου, Μαρία | N40: 12.3.1967 | O40: 44829 | P40: Θεσσαλονίκη | Q40: Βαλκανικό Πρωτάθλημα
A41: Female | B41: Βαλκανική Σκυτάλη | C41: 45 | D41: Α | E41: 4.51.57 | F41: Εθνική Ομάδα | G41: Μαραγιάννη, Χριστίνα | H41: 25.11.1972 | I41: Δάφτσου, Άννα | J41: 25.10.1970 | K41: Μουρατίδου, Μαρία | L41: 12.3.1967 | M41: Βαϊνά, Αθηνά | N41: 8.12.59 | O41: 43731 | P41: Τσέλιε, Σλοβενία | Q41: Βαλκανικό Πρωτάθλημα
A42: Female | B42: Βαλκανική Σκυτάλη | C42: 50 | D42: Α | E42: 6.21.82 | F42: Εθνική Ομάδα | G42: Νοικοκυράκη, Ελένη | H42: 16.04.1958 | I42: Μπελαδάκη, Αντωνία | J42: 23.05.1969 | K42: Σιδερίδου, Παρασκευή | L42: 23.09.1967 | M42: Χρυσούλα Δημητροπούλου | N42: 25.08.1966 | O42: 44829 | P42: Θεσσαλονίκη | Q42: Βαλκανικό Πρωτάθλημα
A43: Mixed | B43: 4x100 | C43: 45 | D43: Α | E43: 1.18.41 | F43: Μικτή Ομάδα | G43: Βενέτη, Φωτεινή | I43: Σπιτάλα, Οξανα | K43: Παριγόρης, Κωνσταντίνος | M43: Καστερίδης, Ευστράτιος | N43: 10.11.1954 | O43: 45899 | P43: Βαραζντιν, Κροατία | Q43: Βαλκανικό Πρωτάθλημα
...

Sheet Names
A1: Name | B1: DOB | C1: PROGRAM
A2: Αγνωστος
A3: Άγρος, Οδυσσέας | B3: 30.10.1957 | C3: =VLOOKUP(A3,'Database Names'!$C$2:$D4262,2,FALSE) -> 21123
A4: Αθανασοπούλου, Κρυσταλλία | B4: 18.05.1970 | C4: =VLOOKUP(A4,'Database Names'!$C$2:$D4263,2,FALSE) -> 25706
A5: Αλέξης, Γεώργιος | B5: 3.5.1959 | C5: =VLOOKUP(A5,'Database Names'!$C$2:$D4264,2,FALSE) -> 21673
A6: Αλλίμονος, Γεώργιος | B6: 20.02.1942 | C6: =VLOOKUP(A6,'Database Names'!$C$2:$D4265,2,FALSE) -> 15392
A7: Ανδρεάδης, Βασίλειος | B7: 14.2.1954 | C7: =VLOOKUP(A7,'Database Names'!$C$2:$D4266,2,FALSE) -> 19769
A8: Ανδρομιδάς, Νικόλαος | B8: 15.04.1972 | C8: =VLOOKUP(A8,'Database Names'!$C$2:$D4267,2,FALSE) -> 26404
A9: Ανυφαντή, Ελένη
A10: Αρβανίτης, Νικόλαος | B10: 21.8.1967 | C10: =VLOOKUP(A10,'Database Names'!$C$2:$D4269,2,FALSE) -> 24705
A11: Αργυρόπουλος, Διονύσιος | B11: 4.8.1969 | C11: =VLOOKUP(A11,'Database Names'!$C$2:$D4271,2,FALSE) -> 25419
A12: Αρμάος, Ιούλιος | B12: 4.4.1977 | C12: =VLOOKUP(A12,'Database Names'!$C$2:$D4272,2,FALSE) -> 28219
A13: Αφρουδάκης, Παναγιώτης | B13: 21.1.1977 | C13: =VLOOKUP(A13,'Database Names'!$C$2:$D4273,2,FALSE) -> 28146
A14: Βαϊνά, Αθηνά | B14: 8.12.59 | C14: =VLOOKUP(A14,'Database Names'!$C$2:$D4274,2,FALSE) -> 21892
A15: Βενέτη, Φωτεινή | B15: 22.06.1979 | C15: =VLOOKUP(A15,'Database Names'!$C$2:$D4275,2,FALSE) -> 29028
A16: Βλάχος, Ιωάννης | B16: 26.01.1953 | C16: =VLOOKUP(A16,'Database Names'!$C$2:$D4276,2,FALSE) -> 19385
A17: Γεωργιάδου, Βαρβάρα | B17: 22.01.1980 | C17: =VLOOKUP(A17,'Database Names'!$C$2:$D4277,2,FALSE) -> 29242
A18: Γιανναδάκης, Νικόλαος | B18: 25.01.1977 | C18: =VLOOKUP(A18,'Database Names'!$C$2:$D4278,2,FALSE) -> 28150
A19: Γκουζώνης, Γεώργιος | B19: 17.4.1980 | C19: =VLOOKUP(A19,'Database Names'!$C$2:$D4279,2,FALSE) -> 29328
A20: Δάφτσου, Άννα | B20: 25.09.1970 | C20: =VLOOKUP(A20,'Database Names'!$C$2:$D4280,2,FALSE) -> 25836
A21: Δημητρόπουλος, Κωνσταντίνος | B21: 13.10.1937 | C21: =VLOOKUP(A21,'Database Names'!$C$2:$D4281,2,FALSE) -> 13801
A22: Δημητροπούλου, Χρυσούλα | B22: 25.08.1966 | C22: =VLOOKUP(A22,'Database Names'!$C$2:$D4282,2,FALSE) -> 24344
... A26: Δρουδάκης, Ιωάννης | B26: 16.8.1953 | C26: =VLOOKUP(A26,'Database Names'!$C$2:$D4286,2,FALSE) -> 19587
A27: Ευαγγελοπούλου, Καίτη
A28: Ζογλοπίτης, Ιωάννης | B28: 2.9.1968 | C28: =VLOOKUP(A28,'Database Names'!$C$2:$D4288,2,FALSE) -> 25083
A29: Θωμάιδου, Αναστασία | B29: 30.1.1978 | C29: =VLOOKUP(A29,'Database Names'!$C$2:$D4289,2,FALSE) -> 28520
A30: Ιερωνυμάκη
A31: Καπασακάλης, Κοσμάς | B31: 9.6.1934 | C31: =VLOOKUP(A31,'Database Names'!$C$2:$D4291,2,FALSE) -> 12579
A32: Καπασούζ, Ιορδάνης | B32: 29.8.1980 | C32: =VLOOKUP(A32,'Database Names'!$C$2:$D4292,2,FALSE) -> 29462
A33: Καραγιαννόπουλος, Σ. | B33: 10.7.1960 | C33: =VLOOKUP(A33,'Database Names'!$C$2:$D4293,2,FALSE) -> 22107
A34: Καστερίδης, Ευστράτιος | B34: 10.11.1954 | C34: =VLOOKUP(A34,'Database Names'!$C$2:$D4294,2,FALSE) -> 20038
A35: Καταντωνάκης, Αντώνιος | B35: 21.09.1977 | C35: =VLOOKUP(A35,'Database Names'!$C$2:$D4295,2,FALSE) -> 28389
A36: Κόκκος, Νικόλαος | B36: 2.10.1969 | C36: =VLOOKUP(A36,'Database Names'!$C$2:$D4296,2,FALSE) -> 25478
A37: Κομματάς, Κωνσταντίνος | B37: 28.10.1957 | C37: =VLOOKUP(A37,'Database Names'!$C$2:$D4297,2,FALSE) -> 21121
A38: Κοντονής, Διονύσιος | B38: 6.2.1969 | C38: =VLOOKUP(A38,'Database Names'!$C$2:$D4298,2,FALSE) -> 25240
A39: Κουνούπης, Γ. | B39: 20.6.1957 | C39: =VLOOKUP(A39,'Database Names'!$C$2:$D4299,2,FALSE) -> 20991
A40: Κουρής, Νικόλαος
A41: Κουτσώνας, Αλέξανδρος
A42: Κυριάκος, Ιωάννης | B42: 9.2.1979 | C42: =VLOOKUP(A42,'Database Names'!$C$2:$D4302,2,FALSE) -> 28895
A43: Κυρίμης, Δημήτριος | B43: 24.2.1956 | C43: =VLOOKUP(A43,'Database Names'!$C$2:$D4303,2,FALSE) -> 20509
...

Sheet Database Names
A1: Last Name | B1: First Name | C1: N | D1: Date of Birth | E1: Gender
A2: Αγγλούπας | B2: Στυλιανός | C2: =CONCATENATE(A2,", ",B2) -> Αγγλούπας, Στυλιανός | D2: 17246 | E2: Male
A3: Άγρος | B3: Οδυσσέας | C3: =CONCATENATE(A3,", ",B3) -> Άγρος, Οδυσσέας | D3: 21123 | E3: Male
A4: Αθανασιος | B4: Τσελιος | C4: =CONCATENATE(A4,", ",B4) -> Αθανασιος, Τσελιος | D4: 21774 | E4: Male
A5: Αθανασοπούλου | B5: Κρυσταλλία | C5: =CONCATENATE(A5,", ",B5) -> Αθανασοπούλου, Κρυσταλλία | D5: 25706 | E5: Female
A6: Αλέξης | B6: Γεώργιος | C6: =CONCATENATE(A6,", ",B6) -> Αλέξης, Γεώργιος | D6: 21673 | E6: Male
A7: Αλεξόπουλος | B7: Νικόλαος | C7: =CONCATENATE(A7,", ",B7) -> Αλεξόπουλος, Νικόλαος | D7: 14977 | E7: Male
A8: Αλλίμονος | B8: Γεώργιος | C8: =CONCATENATE(A8,", ",B8) -> Αλλίμονος, Γεώργιος | D8: 15392 | E8: Male
A9: Αμπατζή | B9: Αρετή | C9: =CONCATENATE(A9,", ",B9) -> Αμπατζή, Αρετή | D9: 27163 | E9: Female
A10: Αμπατζίδου | B10: Γεωργία | C10: =CONCATENATE(A10,", ",B10) -> Αμπατζίδου, Γεωργία | D10: 25281 | E10: Female
A11: Αναγνώστου | B11: Θεόδωρος | C11: =CONCATENATE(A11,", ",B11) -> Αναγνώστου, Θεόδωρος | D11: 27556 | E11: Male
A12: Ανδρεάδης | B12: Βασίλειος | C12: =CONCATENATE(A12,", ",B12) -> Ανδρεάδης, Βασίλειος | D12: 19769 | E12: Male
A13: Ανδρέογλου | B13: Ευθύμιος | C13: =CONCATENATE(A13,", ",B13) -> Ανδρέογλου, Ευθύμιος | D13: 25792 | E13: Male
... A262: Ψαρογιώργος | B262: Χρήστος | C262: =CONCATENATE(A262,", ",B262) -> Ψαρογιώργος, Χρήστος | D262: 27357 | E262: Male
